<?xml version="1.0" encoding="utf-8"?>
<robot
  name="ezj">
<!-- <joint name="gripper_base_joint" type="fixed">
    <origin xyz="0.045 0.039 0.051" rpy="-1.5708 -1.5708 0" />
    <parent link="Camera_base_link" />
    <child link="gripper_base_link" />
  </joint> -->

  <link name="gripper_base_link">
    <inertial>
      <origin xyz="0.00339303654278191 -2.1205433560656E-05 -0.0099185365078758" rpy="0 0 0" />
      <mass value="0.105853592307918" />
      <inertia ixx="3.93795927851199E-05" ixy="-8.7395226509728E-08" ixz="5.91928672040786E-07" iyy="0.000106376720416166" iyz="-1.82858764303774E-10" izz="0.000125852616063213" />
    </inertial>
    <visual>
      <origin xyz="0 0 0" rpy="0 0 0" />
      <geometry>
        <mesh filename="./meshes/gripper/base_link.STL" />
      </geometry>
      <material name="">
        <color rgba="0.894117647058823 0.913725490196078 0.929411764705882 1" />
      </material>
    </visual>
    <collision>
      <origin xyz="0 0 0" rpy="0 0 0" />
      <geometry>
        <mesh filename="./meshes/gripper/base_link.STL" />
      </geometry>
    </collision>
  </link>

  <joint name="joint_b1" type="revolute">
    <origin xyz="0.036 -0.04 -0.019" rpy="0 0 0.55" />
    <parent link="gripper_base_link" />
    <child link="gripper_link1" />
    <axis xyz="0 0 1" />
    <limit lower="-0.75" upper="0" effort="1" velocity="1" />
  </joint>

  <link name="gripper_link1">
    <inertial>
      <origin xyz="0.0164149658242926 0.00898193900447147 0.00898193900447147" rpy="0 0 0" />
      <mass value="0.00647716099397792" />
      <inertia ixx="2.95068972140683E-07" ixy="8.63208170411155E-13" ixz="-1.92008628754607E-09" iyy="1.69979619476872E-06" iyz="-1.99232397395103E-13" izz="1.45016449434989E-06" />
    </inertial>
    <visual>
      <origin xyz="0 0 0" rpy="0 0 0" />
      <geometry>
        <mesh filename="./meshes/gripper/Link1.STL" />
      </geometry>
      <material name="">
        <color rgba="0.894117647058823 0.913725490196078 0.929411764705882 1" />
      </material>
    </visual>
    <collision>
      <origin xyz="0 0 0" rpy="0 0 0" />
      <geometry>
        <mesh filename="./meshes/gripper/Link1.STL" />
      </geometry>
    </collision>
  </link>

  <joint
    name="joint_13"
    type="revolute">
    <!-- <origin
      xyz="0.042 0 0.003"
      rpy="5.0393E-16 5.6225E-16 0.30719" /> -->
    <origin
      xyz="0.042 0 0.003"
      rpy="5.0393E-16 5.6225E-16 -0.55" />
    <parent
      link="gripper_link1" />
    <child
      link="gripper_link3" />
    <axis xyz="0 0 1" />
  <limit lower="0" upper="1.57" effort="1" velocity="1" />
  <mimic joint="joint_b1" multiplier="-1.0" offset="0.0" /> <!-- mimic 属性 -->
</joint>

  <link
    name="gripper_link3">
    <inertial>
      <origin
        xyz="0.011366555972498 -0.0118642725662323 0.0060000073930068"
        rpy="0 0 0" />
      <mass
        value="0.0127543420299361" />
      <inertia
        ixx="5.68538478020233E-07"
        ixy="-2.68012262729007E-07"
        ixz="9.34125984931838E-13"
        iyy="1.45145776457487E-06"
        iyz="9.34355360561326E-13"
        izz="1.50564598220449E-06" />
    </inertial>
    <visual>
      <origin
        xyz="0 0 0"
        rpy="0 0 0" />
      <geometry>
        <mesh
          filename="./meshes/gripper/Link3.STL" />
      </geometry>
      <material
        name="">
        <color
          rgba="0.894117647058823 0.913725490196078 0.929411764705882 1" />
      </material>
    </visual>
    <collision>
      <origin
        xyz="0 0 0"
        rpy="0 0 0" />
      <geometry>
        <mesh
          filename="./meshes/gripper/Link3.STL" />
      </geometry>
    </collision>
  </link>


  <joint name="joint_b2" type="revolute">
    <origin xyz="0.036 0.04 -0.019" rpy="0 0 -0.55" />
    <parent link="gripper_base_link" />
    <child link="gripper_link2" />
    <axis xyz="0 0 1" />
    <limit lower="0" upper="0.75" effort="1" velocity="1" />
    <mimic joint="joint_b1" multiplier="-1.0" offset="0.0" /> <!-- mimic 属性 -->
  </joint>

  <link name="gripper_link2">
    <inertial>
      <origin xyz="0.0164149658242926 0.00898193900447147 0.00898193900447147" rpy="0 0 0" />
      <mass value="0.00647716099397792" />
      <inertia ixx="2.95068972140683E-07" ixy="8.63208170411155E-13" ixz="-1.92008628754607E-09" iyy="1.69979619476872E-06" iyz="-1.99232397395103E-13" izz="1.45016449434989E-06" />
    </inertial>
    <visual>
      <origin xyz="0 0 0" rpy="0 0 0" />
      <geometry>
        <mesh filename="./meshes/gripper/Link2.STL" />
      </geometry>
      <material name="">
        <color rgba="0.894117647058823 0.913725490196078 0.929411764705882 1" />
      </material>
    </visual>
    <collision>
      <origin xyz="0 0 0" rpy="0 0 0" />
      <geometry>
        <mesh filename="./meshes/gripper/Link2.STL" />
      </geometry>
    </collision>
  </link>

  <joint
    name="joint_24"
    type="revolute">
    <origin
      xyz="0.042 0 0.015"
      rpy="-3.641E-16 2.4584E-16 -2.589" />
    <parent
      link="gripper_link2" />
    <child
      link="gripper_link4" />
    <axis
      xyz="0 0 1" />
    <limit lower="-1.57" upper="0" effort="1" velocity="1" />
    <mimic joint="joint_b2" multiplier="-1.0" offset="0.0" /> <!-- mimic 属性 -->
  </joint>

  <link
    name="gripper_link4">
    <inertial>
      <origin
        xyz="-0.011366555972498 0.0118642725662323 -0.0060000073930068"
        rpy="0 0 0" />
      <mass
        value="0.0127543420299362" />
      <inertia
        ixx="5.68538478020238E-07"
        ixy="2.6801226272901E-07"
        ixz="9.34125986250171E-13"
        iyy="1.45145776457489E-06"
        iyz="-9.34355361631596E-13"
        izz="1.5056459822045E-06" />
    </inertial>
    <visual>
      <origin
        xyz="0 0 0"
        rpy="0 0 0" />
      <geometry>
        <mesh
          filename="./meshes/gripper/Link4.STL" />
      </geometry>
      <material
        name="">
        <color
          rgba="0.894117647058823 0.913725490196078 0.929411764705882 1" />
      </material>
    </visual>
    <collision>
      <origin
        xyz="0 0 0"
        rpy="0 0 0" />
      <geometry>
        <mesh
          filename="./meshes/gripper/Link4.STL" />
      </geometry>
    </collision>
  </link>
</robot>