<?xml version="1.0" encoding="utf-8"?>
<robot
  name="rm_65_description">
  <link
    name="base_link">
    <inertial>
      <origin
        xyz="-0.000433277303987328 -3.54664423471128E-05 0.0599427668933796"
        rpy="0 0 0" />
      <mass
        value="0.841070778135659" />
      <inertia
        ixx="0.0017261110801622"
        ixy="2.52746264980217E-06"
        ixz="-3.67690303614961E-05"
        iyy="0.00170987405835604"
        iyz="1.67996364994424E-06"
        izz="0.000904023422915791" />
    </inertial>
    <visual>
      <origin
        xyz="0 0 0"
        rpy="0 0 0" />
      <geometry>
        <mesh
          filename="./meshes/rm_65_arm/base_link.STL" />
      </geometry>
      <material
        name="">
        <color
          rgba="1 1 1 1" />
      </material>
    </visual>
    <collision>
      <origin
        xyz="0 0 0"
        rpy="0 0 0" />
      <geometry>
        <mesh
          filename="./meshes/rm_65_arm/base_link.STL" />
          <!-- filename="package://rm_description/meshes/rm_65_arm/base_link.STL" /> -->
      </geometry>
    </collision>
  </link>
  <link
    name="Link1">
    <inertial>
      <origin
        xyz="1.2226305431569E-08 0.0211079974844683 -0.0251854220842269"
        rpy="0 0 0" />
      <mass
        value="0.593563443690403" />
      <inertia
        ixx="0.00126614120341847"
        ixy="-1.294980943835E-08"
        ixz="-9.80120923066996E-09"
        iyy="0.00118168178300364"
        iyz="-0.00021121727444415"
        izz="0.00056135241627747" />
    </inertial>
    <visual>
      <origin
        xyz="0 0 0"
        rpy="0 0 0" />
      <geometry>
        <mesh
          filename="./meshes/rm_65_arm/link1.STL" />
      </geometry>
      <material
        name="">
        <color
          rgba="1 1 1 1" />
      </material>
    </visual>
    <collision>
      <origin
        xyz="0 0 0"
        rpy="0 0 0" />
      <geometry>
        <mesh
          filename="./meshes/rm_65_arm/link1.STL" />
      </geometry>
    </collision>
  </link>
  <joint
    name="joint1"
    type="revolute">
    <origin
      xyz="0 0 0.2405"
      rpy="0 0 0" />
    <parent
      link="base_link" />
    <child
      link="Link1" />
    <axis
      xyz="0 0 1" />
    <limit
      lower="-3.1"
      upper="3.1"
      effort="60"
      velocity="3.14" />
  </joint>
  <link
    name="Link2">
    <inertial>
      <origin
        xyz="0.152256463426163 4.75383656106654E-07 -0.00620260383607792"
        rpy="0 0 0" />
      <mass
        value="0.864175046869043" />
      <inertia
        ixx="0.00089150298478414"
        ixy="-2.23268489334765E-08"
        ixz="0.00156246461035015"
        iyy="0.00733754343083901"
        iyz="6.28110889329165E-09"
        izz="0.00697869103915473" />
    </inertial>
    <visual>
      <origin
        xyz="0 0 0"
        rpy="0 0 0" />
      <geometry>
        <mesh
          filename="./meshes/rm_65_arm/link2.STL" />
      </geometry>
      <material
        name="">
        <color
          rgba="1 1 1 1" />
      </material>
    </visual>
    <collision>
      <origin
        xyz="0 0 0"
        rpy="0 0 0" />
      <geometry>
        <mesh
          filename="./meshes/rm_65_arm/link2.STL" />
      </geometry>
    </collision>
  </link>
  <joint
    name="joint2"
    type="revolute">
    <origin
      xyz="0 0 0"
      rpy="1.5708 -1.5708 0" />
    <parent
      link="Link1" />
    <child
      link="Link2" />
    <axis
      xyz="0 0 1" />
    <limit
      lower="-2.268"
      upper="2.268"
      effort="60"
      velocity="3.14" />
  </joint>
  <link
    name="Link3">
    <inertial>
      <origin
        xyz="5.05312670989961E-06 -0.0595925663694732 0.010569069212336"
        rpy="0 0 0" />
      <mass
        value="0.289633681624654" />
      <inertia
        ixx="0.00063737100450158"
        ixy="-7.05261293649751E-08"
        ixz="-3.86643272239426E-08"
        iyy="0.00015648388095025"
        iyz="-0.00014461035994916"
        izz="0.000614178164773085" />
    </inertial>
    <visual>
      <origin
        xyz="0 0 0"
        rpy="0 0 0" />
      <geometry>
        <mesh
          filename="./meshes/rm_65_arm/link3.STL" />
      </geometry>
      <material
        name="">
        <color
          rgba="1 1 1 1" />
      </material>
    </visual>
    <collision>
      <origin
        xyz="0 0 0"
        rpy="0 0 0" />
      <geometry>
        <mesh
          filename="./meshes/rm_65_arm/link3.STL" />
      </geometry>
    </collision>
  </link>
  <joint
    name="joint3"
    type="revolute">
    <origin
      xyz="0.256 0 0"
      rpy="0 0 1.5708" />
    <parent
      link="Link2" />
    <child
      link="Link3" />
    <axis
      xyz="0 0 1" />
    <limit
      lower="-2.355"
      upper="2.355"
      effort="30"
      velocity="3.92" />
  </joint>
  <link
    name="Link4">
    <inertial>
      <origin
        xyz="1.15516617405898E-06 -0.0180424468598241 -0.0215394748352687"
        rpy="0 0 0" />
      <mass
        value="0.239419768320061" />
      <inertia
        ixx="0.000285938919722783"
        ixy="3.07101359163101E-09"
        ixz="-2.21994118981953E-09"
        iyy="0.000262727540304212"
        iyz="4.4236583260078E-05"
        izz="0.000119888082791859" />
    </inertial>
    <visual>
      <origin
        xyz="0 0 0"
        rpy="0 0 0" />
      <geometry>
        <mesh
          filename="./meshes/rm_65_arm/link4.STL" />
      </geometry>
      <material
        name="">
        <color
          rgba="1 1 1 1" />
      </material>
    </visual>
    <collision>
      <origin
        xyz="0 0 0"
        rpy="0 0 0" />
      <geometry>
        <mesh
          filename="./meshes/rm_65_arm/link4.STL" />
      </geometry>
    </collision>
  </link>
  <joint
    name="joint4"
    type="revolute">
    <origin
      xyz="0 -0.21 0"
      rpy="1.5708 0 0" />
    <parent
      link="Link3" />
    <child
      link="Link4" />
    <axis
      xyz="0 0 1" />
    <limit
      lower="-3.1"
      upper="3.1"
      effort="10"
      velocity="3.92" />
  </joint>
  <link
    name="Link5">
    <inertial>
      <origin
        xyz="3.19794786262152E-06 -0.0593808368101458 0.00736804250989326"
        rpy="0 0 0" />
      <mass
        value="0.218799761431678" />
      <inertia
        ixx="0.000350540363914072"
        ixy="-3.41781619975602E-08"
        ixz="-1.77056457224373E-08"
        iyy="0.000104927867487581"
        iyz="-7.82431228461971E-05"
        izz="0.000334482418423629" />
    </inertial>
    <visual>
      <origin
        xyz="0 0 0"
        rpy="0 0 0" />
      <geometry>
        <mesh
          filename="./meshes/rm_65_arm/link5.STL" />
      </geometry>
      <material
        name="">
        <color
          rgba="1 1 1 1" />
      </material>
    </visual>
    <collision>
      <origin
        xyz="0 0 0"
        rpy="0 0 0" />
      <geometry>
        <mesh
          filename="./meshes/rm_65_arm/link5.STL" />
      </geometry>
    </collision>
  </link>
  <joint
    name="joint5"
    type="revolute">
    <origin
      xyz="0 0 0"
      rpy="-1.5708 0 0" />
    <parent
      link="Link4" />
    <child
      link="Link5" />
    <axis
      xyz="0 0 1" />
    <limit
      lower="-2.233"
      upper="2.233"
      effort="10"
      velocity="3.92" />
  </joint>

    <joint
    name="joint6"
    type="revolute">
    <origin
      xyz="0 -0.144 0"
      rpy="1.5708 0 0" />
    <parent
      link="Link5" />
    <child
      link="Link6" />
    <axis
      xyz="0 0 1" />
    <limit
      lower="-6.28"
      upper="6.28"
      effort="10"
      velocity="3.92" />
  </joint>
  <link
    name="Link6">
    <inertial>
      <origin
        xyz="0.000714234511756999 -0.000396718732824521 -0.0126723660946126"
        rpy="0 0 0" />
      <mass
        value="0.0649018034311231" />
      <inertia
        ixx="2.02766547502765E-05"
        ixy="-1.32505200276849E-06"
        ixz="-2.5845091522508E-08"
        iyy="1.87986725225022E-05"
        iyz="3.39471452125439E-09"
        izz="3.17885459163081E-05" />
    </inertial>
    <visual>
      <origin
        xyz="0 0 0"
        rpy="0 0 0" />
      <geometry>
        <mesh
          filename="./meshes/rm_65_arm/link6.STL" />
      </geometry>
      <material
        name="">
        <color
          rgba="1 1 1 1" />
      </material>
    </visual>
    <collision>
      <origin
        xyz="0 0 0"
        rpy="0 0 0" />
      <geometry>
        <mesh
          filename="./meshes/rm_65_arm/link6.STL" />
      </geometry>
    </collision>
  </link>

  <joint
    name="joint7"
    type="fixed">
    <origin xyz="0.048 -0.025 0" rpy="0 0 2.0944" />
    <parent
      link="Link6" />
    <child
      link="Camera_base_link" />
  </joint>

  <link
    name="Camera_base_link">
    <inertial>
      <origin
        xyz="0 0 0"
        rpy="0 0 0" />
      <mass
        value="0.02" />
      <inertia ixx="0" ixy="0" ixz="0" iyy="0" iyz="0" izz="0" />
    </inertial>
    <visual>
      <origin
        xyz="0 0 0"
        rpy="0 0 0" />
      <geometry>
        <mesh
          filename="./meshes/camera/camera_stander_no_hole.STL" />
      </geometry>
      <material name="custom_color">
       <!--  <color rgba="0 1 0 1" /> Green color, fully opaque -->
      </material>
    </visual>
    <collision>
      <origin
        xyz="0 0 0"
        rpy="0 0 0" />
      <geometry>
        <mesh
          filename="./meshes/camera/camera_stander_no_hole.STL" />
      </geometry>
    </collision>
  </link>

  <!--  相机URDF模型  -->
  <link name="camera_link">
    <visual>
      <origin xyz="0.01 -0.0175 0.0" rpy="1.5708 0 1.5708"/>
      <geometry>
        <mesh filename="./meshes/camera/d435.dae" scale="1 1 1"/>
      </geometry>
      <material name="aluminum">
        <color rgba="0.5 0.5 0.5 1"/>
      </material>
    </visual>
    <collision>
      <origin xyz="-0.002 -0.0175 0.0" rpy="1.5708 1.5708 1.5708"/>
      <geometry>
        <box size="0.02505 0.09 0.025"/>
      </geometry>
    </collision>
    <inertial>
      <mass value="0.564"/>
      <inertia ixx="0.003881" ixy="0" ixz="0" iyy="0.000499" iyz="0" izz="0.003879"/>
    </inertial>
  </link>

  <!-- D435引入 -->
  <joint name="camera_joint" type="fixed">
    <parent link="Camera_base_link"/>  <!-- 修改为你的机械臂末端链接名 -->
    <child link="camera_link"/>
   <!-- <origin xyz="0.062 0.1215 0.0225" rpy="1.5708 -1.5708 3.1416"/>   调整安装位置 -->
    <origin xyz="0.062 0.055 0.0225" rpy="1.5708 -1.5708 3.1416"/>  <!-- 调整安装位置 -->
  </joint>




 
  <!-- 添加 WSG50 夹爪 -->
  <joint name="wsg50_base_joint" type="fixed">
    <origin xyz="0.046 0.028 0.008" rpy="0 0 0" />
    <parent link="Camera_base_link" />
    <child link="wsg50_base_link" />
  </joint>

  <link name="wsg50_base_link">
    <inertial>
      <origin xyz="0 0 0" rpy="0 0 0"/>
      <mass value="0.15"/>
      <inertia ixx="0.03125" ixy="0" ixz="0" iyy="0.03125" iyz="0" izz="0.03125"/>
    </inertial>
    <visual>
      <origin xyz="0 0 0" rpy="0 0 0"/>
      <geometry>
        <mesh filename="./gripper/meshes/WSG50_110.stl" scale="0.5 0.5 0.5"/>
      </geometry>
      <material name="wsg50_grey">
        <color rgba="0.5 0.5 0.5 1"/>
      </material>
    </visual>
  </link>

  <!-- 电机链接 -->
  <link name="wsg50_motor">
    <inertial>
      <origin xyz="0 0 0" rpy="0 0 0"/>
      <mass value="0.0125"/>
      <inertia ixx="0.003125" ixy="0" ixz="0" iyy="0.003125" iyz="0" izz="0.003125"/>
    </inertial>
    <visual>
      <origin xyz="0 0 0.005" rpy="0 0 0"/>
      <geometry>
        <box size="0.01 0.01 0.01"/>
      </geometry>
      <material name="wsg50_dark_grey">
        <color rgba="0.3 0.3 0.3 1"/>
      </material>
    </visual>
  </link>

  <joint name="wsg50_base_joint_motor" type="prismatic">
    <parent link="wsg50_base_link"/>
    <child link="wsg50_motor"/>
    <origin xyz="0 0 0.015" rpy="0 0 0"/>
    <axis xyz="0 0 1"/>
    <limit lower="-0.0275" upper="0.0005" effort="10" velocity="10"/>
    <dynamics damping="0" friction="0"/>
  </joint>

  <!-- 左铰链 -->
  <link name="wsg50_left_hinge">
    <inertial>
      <origin xyz="0 0 0.0175" rpy="0 0 0"/>
      <mass value="0.0125"/>
      <inertia ixx="0.003125" ixy="0" ixz="0" iyy="0.003125" iyz="0" izz="0.003125"/>
    </inertial>
    <visual>
      <origin xyz="-0.015 0 0.005" rpy="0 -1.2 0"/>
      <geometry>
        <box size="0.01 0.01 0.035"/>
      </geometry>
      <material name="wsg50_dark_grey"/>
    </visual>
  </link>

  <joint name="wsg50_motor_left_hinge_joint" type="revolute">
    <parent link="wsg50_motor"/>
    <child link="wsg50_left_hinge"/>
    <origin xyz="0 0 0.005" rpy="0 0 0"/>
    <axis xyz="0 1 0"/>
    <limit lower="-20" upper="20" effort="10" velocity="10"/>
    <dynamics damping="0" friction="0"/>
  </joint>

  <!-- 右铰链 -->
  <link name="wsg50_right_hinge">
    <inertial>
      <origin xyz="0 0 0.0175" rpy="0 0 0"/>
      <mass value="0.0125"/>
      <inertia ixx="0.003125" ixy="0" ixz="0" iyy="0.003125" iyz="0" izz="0.003125"/>
    </inertial>
    <visual>
      <origin xyz="0.015 0 0.005" rpy="0 1.2 0"/>
      <geometry>
        <box size="0.01 0.01 0.035"/>
      </geometry>
      <material name="wsg50_dark_grey"/>
    </visual>
  </link>

  <joint name="wsg50_motor_right_hinge_joint" type="revolute">
    <parent link="wsg50_motor"/>
    <child link="wsg50_right_hinge"/>
    <origin xyz="0 0 0.005" rpy="0 0 0"/>
    <axis xyz="0 1 0"/>
    <limit lower="-20" upper="20" effort="10" velocity="10"/>
    <dynamics damping="0" friction="0"/>
  </joint>

  <!-- 左夹爪滑块 -->
  <link name="wsg50_gripper_left">
    <inertial>
      <origin xyz="0 0 0.00575" rpy="0 0 0"/>
      <mass value="0.025"/>
      <inertia ixx="0.003125" ixy="0" ixz="0" iyy="0.003125" iyz="0" izz="0.003125"/>
    </inertial>
    <visual>
      <origin xyz="0 0 -0.03" rpy="0 0 0"/>
      <geometry>
        <mesh filename="./gripper/meshes/GUIDE_WSG50_110.stl" scale="0.0005 0.0005 0.0005"/>
      </geometry>
      <material name="wsg50_grey"/>
    </visual>
    <visual>
      <origin xyz="0 0 -0.0185" rpy="0 0 0"/>
      <geometry>
        <mesh filename="./gripper/meshes/WSG-FMF.stl" scale="0.0005 0.0005 0.0005"/>
      </geometry>
      <material name="wsg50_grey"/>
    </visual>
  </link>

  <joint name="wsg50_finger_left_joint" type="prismatic">
    <parent link="wsg50_base_link"/>
    <child link="wsg50_gripper_left"/>
    <origin xyz="-0.0275 0 0.03" rpy="0 0 0"/>
    <axis xyz="1 0 0"/>
    <limit lower="-0.005" upper="0.025" effort="1" velocity="1"/>
    <dynamics damping="0" friction="0"/>
  </joint>

  <!-- 右夹爪滑块 -->
  <link name="wsg50_gripper_right">
    <inertial>
      <origin xyz="0 0 0.00575" rpy="0 0 0"/>
      <mass value="0.025"/>
      <inertia ixx="0.003125" ixy="0" ixz="0" iyy="0.003125" iyz="0" izz="0.003125"/>
    </inertial>
    <visual>
      <origin xyz="0 0 -0.03" rpy="0 0 0"/>
      <geometry>
        <mesh filename="./gripper/meshes/GUIDE_WSG50_110.stl" scale="0.0005 0.0005 0.0005"/>
      </geometry>
      <material name="wsg50_grey"/>
    </visual>
    <visual>
      <origin xyz="0 0 -0.0185" rpy="0 0 0"/>
      <geometry>
        <mesh filename="./gripper/meshes/WSG-FMF.stl" scale="0.0005 0.0005 0.0005"/>
      </geometry>
      <material name="wsg50_grey"/>
    </visual>
  </link>

  <joint name="wsg50_finger_right_joint" type="prismatic">
    <parent link="wsg50_base_link"/>
    <child link="wsg50_gripper_right"/>
    <origin xyz="0.0275 0 0.03" rpy="0 0 3.14159"/>
    <axis xyz="1 0 0"/>
    <limit lower="-0.005" upper="0.025" effort="1" velocity="1"/>
    <dynamics damping="0" friction="0"/>
  </joint>

  <!-- 左手指 -->
  <link name="wsg50_finger_left">
    <inertial>
      <origin xyz="0 0 0" rpy="0 0 0"/>
      <mass value="0.025"/>
      <inertia ixx="0.003125" ixy="0" ixz="0" iyy="0.003125" iyz="0" izz="0.003125"/>
    </inertial>
    <visual>
      <origin xyz="0 0 0" rpy="0 0 0"/>
      <geometry>
        <mesh filename="./gripper/meshes/l_gripper_tip_scaled.stl" scale="0.5 0.5 0.5"/>
      </geometry>
      <material name="wsg50_blue">
        <color rgba="0.2 0.2 0.8 1"/>
      </material>
    </visual>
    <collision>
      <origin xyz="0 0 0.021" rpy="0 0 0"/>
      <geometry>
        <box size="0.01 0.01 0.075"/>
      </geometry>
    </collision>
  </link>

  <joint name="wsg50_gripper_finger_left" type="fixed">
    <parent link="wsg50_gripper_left"/>
    <child link="wsg50_finger_left"/>
    <origin xyz="-0.0035 0 0.0425" rpy="0 0 4.71239"/>
  </joint>

  <!-- 右手指 -->
  <link name="wsg50_finger_right">
    <inertial>
      <origin xyz="0 0 0" rpy="0 0 0"/>
      <mass value="0.025"/>
      <inertia ixx="0.003125" ixy="0" ixz="0" iyy="0.003125" iyz="0" izz="0.003125"/>
    </inertial>
    <visual>
      <origin xyz="0 0 0" rpy="0 0 0"/>
      <geometry>
        <mesh filename="./gripper/meshes/l_gripper_tip_scaled.stl" scale="0.5 0.5 0.5"/>
      </geometry>
      <material name="wsg50_blue">
        <color rgba="0.2 0.2 0.8 1"/>
      </material>
    </visual>
    <collision>
      <origin xyz="0 0 0.021" rpy="0 0 0"/>
      <geometry>
        <box size="0.01 0.01 0.075"/>
      </geometry>
    </collision>
  </link>

  <joint name="wsg50_gripper_finger_right" type="fixed">
    <parent link="wsg50_gripper_right"/>
    <child link="wsg50_finger_right"/>
    <origin xyz="-0.0035 0 0.0425" rpy="0 0 -1.5708"/>
  </joint>

</robot>

